Workbook
Name County: 'Dropdown Menu'!$B$1:$B$101
Name Flow: 'Dropdown Menu'!$F$1:$F$3
Name Month: 'Dropdown Menu'!$A$1:$A$13
Name Parameters: 'PCS Parameter Codes'!$B$1:$B$76
Name PCS: 'PCS Parameter Codes'!$A$2:$A$76
Name PCSCODE: 'PCS Parameter Codes'!$A$1:$A$76
Name PPI: 'Dropdown Menu'!$D$1:$D$16
Name Sample: 'Dropdown Menu'!$E$1:$E$5
Name SampleType: 'Dropdown Menu'!$E$2:$E$5
Name SamplingType: 'Dropdown Menu'!$E$1:$E$4
Name Year: 'Dropdown Menu'!$C$1:$C$21

Sheet PPI 001
A1: Permit No.: | E1: Facility Name: | L1: County: | O1: Month: | R1: Year:
A2: PPI: | D2: Flow Measuring Point: | K2: Parameter Monitoring Point:
A3: Parameter Code | D3: 50050
A4: Day | B4: ORC Arrival Time | C4: ORC Time On Site | D4: Flow | E4: =IF(ISBLANK(E$3), " ", VLOOKUP(E$3,'PCS Parameter Codes'!$A$1:$D$76,2,FALSE)) | F4: =IF(ISBLANK(F$3), " ", VLOOKUP(F$3,'PCS Parameter Codes'!$A$1:$D$76,2,FALSE)) | G4: =IF(ISBLANK(G$3), " ", VLOOKUP(G$3,'PCS Parameter Codes'!$A$1:$D$76,2,FALSE)) | H4: =IF(ISBLANK(H$3), " ", VLOOKUP(H$3,'PCS Parameter Codes'!$A$1:$D$76,2,FALSE)) | I4: =IF(ISBLANK(I$3), " ", VLOOKUP(I$3,'PCS Parameter Codes'!$A$1:$D$76,2,FALSE)) | J4: =IF(ISBLANK(J$3), " ", VLOOKUP(J$3,'PCS Parameter Codes'!$A$1:$D$76,2,FALSE)) | K4: =IF(ISBLANK(K$3), " ", VLOOKUP(K$3,'PCS Parameter Codes'!$A$1:$D$76,2,FALSE)) | L4: =IF(ISBLANK(L$3), " ", VLOOKUP(L$3,'PCS Parameter Codes'!$A$1:$D$76,2,FALSE)) | ... S4: =IF(ISBLANK(S$3), " ", VLOOKUP(S$3,'PCS Parameter Codes'!$A$1:$D$76,2,FALSE))
B5: 24-hr | C5: hrs | D5: GPD | E5: =IF(ISBLANK(E$3), " ", VLOOKUP(E$3,'PCS Parameter Codes'!$A$1:$D$76,4,FALSE)) | F5: =IF(ISBLANK(F$3), " ", VLOOKUP(F$3,'PCS Parameter Codes'!$A$1:$D$76,4,FALSE)) | G5: =IF(ISBLANK(G$3), " ", VLOOKUP(G$3,'PCS Parameter Codes'!$A$1:$D$76,4,FALSE)) | H5: =IF(ISBLANK(H$3), " ", VLOOKUP(H$3,'PCS Parameter Codes'!$A$1:$D$76,4,FALSE)) | I5: =IF(ISBLANK(I$3), " ", VLOOKUP(I$3,'PCS Parameter Codes'!$A$1:$D$76,4,FALSE)) | J5: =IF(ISBLANK(J$3), " ", VLOOKUP(J$3,'PCS Parameter Codes'!$A$1:$D$76,4,FALSE)) | K5: =IF(ISBLANK(K$3), " ", VLOOKUP(K$3,'PCS Parameter Codes'!$A$1:$D$76,4,FALSE)) | L5: =IF(ISBLANK(L$3), " ", VLOOKUP(L$3,'PCS Parameter Codes'!$A$1:$D$76,4,FALSE)) | ... S5: =IF(ISBLANK(S$3), " ", VLOOKUP(S$3,'PCS Parameter Codes'!$A$1:$D$76,4,FALSE))
A6: 1
A7: 2
A8: 3
A9: 4
A10: 5
A11: 6
A12: 7
A13: 8
A14: 9
A15: 10
A16: 11
A17: 12
... A36: 31
A37: Average: | D37: =IF(ISBLANK($P$1)," ",AVERAGE(D6:D36)) | E37: =IF(ISBLANK($C$1)," ", IF(COUNT(E45:E75)=0, " ", IF(E$4="pH"," ", IF(E$4="Fecal Coliform", GEOMEAN(E76:E106), IF(E$4="Total Coliform", GEOMEAN(E76:E106), AVERAGE(E45:E75)))))) | F37: =IF(ISBLANK($C$1)," ", IF(COUNT(F45:F75)=0, " ", IF(F$4="pH"," ", IF(F$4="Fecal Coliform", GEOMEAN(F76:F106), IF(F$4="Total Coliform", GEOMEAN(F76:F106), AVERAGE(F45:F75)))))) | G37: =IF(ISBLANK($C$1)," ", IF(COUNT(G45:G75)=0, " ", IF(G$4="pH"," ", IF(G$4="Fecal Coliform", GEOMEAN(G76:G106), IF(G$4="Total Coliform", GEOMEAN(G76:G106), AVERAGE(G45:G75)))))) | H37: =IF(ISBLANK($C$1)," ", IF(COUNT(H45:H75)=0, " ", IF(H$4="pH"," ", IF(H$4="Fecal Coliform", GEOMEAN(H76:H106), IF(H$4="Total Coliform", GEOMEAN(H76:H106), AVERAGE(H45:H75)))))) | I37: =IF(ISBLANK($C$1)," ", IF(COUNT(I45:I75)=0, " ", IF(I$4="pH"," ", IF(I$4="Fecal Coliform", GEOMEAN(I76:I106), IF(I$4="Total Coliform", GEOMEAN(I76:I106), AVERAGE(I45:I75)))))) | J37: =IF(ISBLANK($C$1)," ", IF(COUNT(J45:J75)=0, " ", IF(J$4="pH"," ", IF(J$4="Fecal Coliform", GEOMEAN(J76:J106), IF(J$4="Total Coliform", GEOMEAN(J76:J106), AVERAGE(J45:J75)))))) | K37: =IF(ISBLANK($C$1)," ", IF(COUNT(K45:K75)=0, " ", IF(K$4="pH"," ", IF(K$4="Fecal Coliform", GEOMEAN(K76:K106), IF(K$4="Total Coliform", GEOMEAN(K76:K106), AVERAGE(K45:K75)))))) | L37: =IF(ISBLANK($C$1)," ", IF(COUNT(L45:L75)=0, " ", IF(L$4="pH"," ", IF(L$4="Fecal Coliform", GEOMEAN(L76:L106), IF(L$4="Total Coliform", GEOMEAN(L76:L106), AVERAGE(L45:L75)))))) | ... S37: =IF(ISBLANK($C$1)," ", IF(COUNT(S45:S75)=0, " ", IF(S$4="pH"," ", IF(S$4="Fecal Coliform", GEOMEAN(S76:S106), IF(S$4="Total Coliform", GEOMEAN(S76:S106), AVERAGE(S45:S75))))))
A38: Daily Maximum: | D38: =IF(ISBLANK($P$1)," ",MAX(D6:D36)) | E38: =IF(ISBLANK($C$1)," ", IF(COUNT(E45:E75)=0, " ", MAX(E107:E137))) | F38: =IF(ISBLANK($C$1)," ", IF(COUNT(F45:F75)=0, " ", MAX(F107:F137))) | G38: =IF(ISBLANK($C$1)," ", IF(COUNT(G45:G75)=0, " ", MAX(G107:G137))) | H38: =IF(ISBLANK($C$1)," ", IF(COUNT(H45:H75)=0, " ", MAX(H107:H137))) | I38: =IF(ISBLANK($C$1)," ", IF(COUNT(I45:I75)=0, " ", MAX(I107:I137))) | J38: =IF(ISBLANK($C$1)," ", IF(COUNT(J45:J75)=0, " ", MAX(J107:J137))) | K38: =IF(ISBLANK($C$1)," ", IF(COUNT(K45:K75)=0, " ", MAX(K107:K137))) | L38: =IF(ISBLANK($C$1)," ", IF(COUNT(L45:L75)=0, " ", MAX(L107:L137))) | ... S38: =IF(ISBLANK($C$1)," ", IF(COUNT(S45:S75)=0, " ", MAX(S107:S137)))
A39: Daily Minimum: | D39: =IF(ISBLANK($P$1)," ",MIN(D6:D36)) | E39: =IF(ISBLANK($C$1)," ", IF(COUNT(E45:E75)=0, " ", MIN(E107:E137))) | F39: =IF(ISBLANK($C$1)," ", IF(COUNT(F45:F75)=0, " ", MIN(F107:F137))) | G39: =IF(ISBLANK($C$1)," ", IF(COUNT(G45:G75)=0, " ", MIN(G107:G137))) | H39: =IF(ISBLANK($C$1)," ", IF(COUNT(H45:H75)=0, " ", MIN(H107:H137))) | I39: =IF(ISBLANK($C$1)," ", IF(COUNT(I45:I75)=0, " ", MIN(I107:I137))) | J39: =IF(ISBLANK($C$1)," ", IF(COUNT(J45:J75)=0, " ", MIN(J107:J137))) | K39: =IF(ISBLANK($C$1)," ", IF(COUNT(K45:K75)=0, " ", MIN(K107:K137))) | L39: =IF(ISBLANK($C$1)," ", IF(COUNT(L45:L75)=0, " ", MIN(L107:L137))) | ... S39: =IF(ISBLANK($C$1)," ", IF(COUNT(S45:S75)=0, " ", MIN(S107:S137)))
A40: Sampling Type:
A41: Monthly Avg. Limit:
A42: Daily Limit:
A43: Sample Frequency:
C45: Average | E45: =IF(ISBLANK(E6), " ",IF(ISTEXT(E6),0,E6)) | F45: =IF(ISBLANK(F6), " ",IF(ISTEXT(F6),0,F6)) | G45: =IF(ISBLANK(G6), " ",IF(ISTEXT(G6),0,G6)) | H45: =IF(ISBLANK(H6), " ",IF(ISTEXT(H6),0,H6)) | I45: =IF(ISBLANK(I6), " ",IF(ISTEXT(I6),0,I6)) | J45: =IF(ISBLANK(J6), " ",IF(ISTEXT(J6),0,J6)) | K45: =IF(ISBLANK(K6), " ",IF(ISTEXT(K6),0,K6)) | L45: =IF(ISBLANK(L6), " ",IF(ISTEXT(L6),0,L6)) | ... S45: =IF(ISBLANK(S6), " ",IF(ISTEXT(S6),0,S6))
E46: =IF(ISBLANK(E7), " ",IF(ISTEXT(E7),0,E7)) | F46: =IF(ISBLANK(F7), " ",IF(ISTEXT(F7),0,F7)) | G46: =IF(ISBLANK(G7), " ",IF(ISTEXT(G7),0,G7)) | H46: =IF(ISBLANK(H7), " ",IF(ISTEXT(H7),0,H7)) | I46: =IF(ISBLANK(I7), " ",IF(ISTEXT(I7),0,I7)) | J46: =IF(ISBLANK(J7), " ",IF(ISTEXT(J7),0,J7)) | K46: =IF(ISBLANK(K7), " ",IF(ISTEXT(K7),0,K7)) | L46: =IF(ISBLANK(L7), " ",IF(ISTEXT(L7),0,L7)) | ... S46: =IF(ISBLANK(S7), " ",IF(ISTEXT(S7),0,S7))
E47: =IF(ISBLANK(E8), " ",IF(ISTEXT(E8),0,E8)) | F47: =IF(ISBLANK(F8), " ",IF(ISTEXT(F8),0,F8)) | G47: =IF(ISBLANK(G8), " ",IF(ISTEXT(G8),0,G8)) | H47: =IF(ISBLANK(H8), " ",IF(ISTEXT(H8),0,H8)) | I47: =IF(ISBLANK(I8), " ",IF(ISTEXT(I8),0,I8)) | J47: =IF(ISBLANK(J8), " ",IF(ISTEXT(J8),0,J8)) | K47: =IF(ISBLANK(K8), " ",IF(ISTEXT(K8),0,K8)) | L47: =IF(ISBLANK(L8), " ",IF(ISTEXT(L8),0,L8)) | ... S47: =IF(ISBLANK(S8), " ",IF(ISTEXT(S8),0,S8))
E48: =IF(ISBLANK(E9), " ",IF(ISTEXT(E9),0,E9)) | F48: =IF(ISBLANK(F9), " ",IF(ISTEXT(F9),0,F9)) | G48: =IF(ISBLANK(G9), " ",IF(ISTEXT(G9),0,G9)) | H48: =IF(ISBLANK(H9), " ",IF(ISTEXT(H9),0,H9)) | I48: =IF(ISBLANK(I9), " ",IF(ISTEXT(I9),0,I9)) | J48: =IF(ISBLANK(J9), " ",IF(ISTEXT(J9),0,J9)) | K48: =IF(ISBLANK(K9), " ",IF(ISTEXT(K9),0,K9)) | L48: =IF(ISBLANK(L9), " ",IF(ISTEXT(L9),0,L9)) | ... S48: =IF(ISBLANK(S9), " ",IF(ISTEXT(S9),0,S9))
E49: =IF(ISBLANK(E10), " ",IF(ISTEXT(E10),0,E10)) | F49: =IF(ISBLANK(F10), " ",IF(ISTEXT(F10),0,F10)) | G49: =IF(ISBLANK(G10), " ",IF(ISTEXT(G10),0,G10)) | H49: =IF(ISBLANK(H10), " ",IF(ISTEXT(H10),0,H10)) | I49: =IF(ISBLANK(I10), " ",IF(ISTEXT(I10),0,I10)) | J49: =IF(ISBLANK(J10), " ",IF(ISTEXT(J10),0,J10)) | K49: =IF(ISBLANK(K10), " ",IF(ISTEXT(K10),0,K10)) | L49: =IF(ISBLANK(L10), " ",IF(ISTEXT(L10),0,L10)) | ... S49: =IF(ISBLANK(S10), " ",IF(ISTEXT(S10),0,S10))
E50: =IF(ISBLANK(E11), " ",IF(ISTEXT(E11),0,E11)) | F50: =IF(ISBLANK(F11), " ",IF(ISTEXT(F11),0,F11)) | G50: =IF(ISBLANK(G11), " ",IF(ISTEXT(G11),0,G11)) | H50: =IF(ISBLANK(H11), " ",IF(ISTEXT(H11),0,H11)) | I50: =IF(ISBLANK(I11), " ",IF(ISTEXT(I11),0,I11)) | J50: =IF(ISBLANK(J11), " ",IF(ISTEXT(J11),0,J11)) | K50: =IF(ISBLANK(K11), " ",IF(ISTEXT(K11),0,K11)) | L50: =IF(ISBLANK(L11), " ",IF(ISTEXT(L11),0,L11)) | ... S50: =IF(ISBLANK(S11), " ",IF(ISTEXT(S11),0,S11))
E51: =IF(ISBLANK(E12), " ",IF(ISTEXT(E12),0,E12)) | F51: =IF(ISBLANK(F12), " ",IF(ISTEXT(F12),0,F12)) | G51: =IF(ISBLANK(G12), " ",IF(ISTEXT(G12),0,G12)) | H51: =IF(ISBLANK(H12), " ",IF(ISTEXT(H12),0,H12)) | I51: =IF(ISBLANK(I12), " ",IF(ISTEXT(I12),0,I12)) | J51: =IF(ISBLANK(J12), " ",IF(ISTEXT(J12),0,J12)) | K51: =IF(ISBLANK(K12), " ",IF(ISTEXT(K12),0,K12)) | L51: =IF(ISBLANK(L12), " ",IF(ISTEXT(L12),0,L12)) | ... S51: =IF(ISBLANK(S12), " ",IF(ISTEXT(S12),0,S12))
E52: =IF(ISBLANK(E13), " ",IF(ISTEXT(E13),0,E13)) | F52: =IF(ISBLANK(F13), " ",IF(ISTEXT(F13),0,F13)) | G52: =IF(ISBLANK(G13), " ",IF(ISTEXT(G13),0,G13)) | H52: =IF(ISBLANK(H13), " ",IF(ISTEXT(H13),0,H13)) | I52: =IF(ISBLANK(I13), " ",IF(ISTEXT(I13),0,I13)) | J52: =IF(ISBLANK(J13), " ",IF(ISTEXT(J13),0,J13)) | K52: =IF(ISBLANK(K13), " ",IF(ISTEXT(K13),0,K13)) | L52: =IF(ISBLANK(L13), " ",IF(ISTEXT(L13),0,L13)) | ... S52: =IF(ISBLANK(S13), " ",IF(ISTEXT(S13),0,S13))
E53: =IF(ISBLANK(E14), " ",IF(ISTEXT(E14),0,E14)) | F53: =IF(ISBLANK(F14), " ",IF(ISTEXT(F14),0,F14)) | G53: =IF(ISBLANK(G14), " ",IF(ISTEXT(G14),0,G14)) | H53: =IF(ISBLANK(H14), " ",IF(ISTEXT(H14),0,H14)) | I53: =IF(ISBLANK(I14), " ",IF(ISTEXT(I14),0,I14)) | J53: =IF(ISBLANK(J14), " ",IF(ISTEXT(J14),0,J14)) | K53: =IF(ISBLANK(K14), " ",IF(ISTEXT(K14),0,K14)) | L53: =IF(ISBLANK(L14), " ",IF(ISTEXT(L14),0,L14)) | ... S53: =IF(ISBLANK(S14), " ",IF(ISTEXT(S14),0,S14))
E54: =IF(ISBLANK(E15), " ",IF(ISTEXT(E15),0,E15)) | F54: =IF(ISBLANK(F15), " ",IF(ISTEXT(F15),0,F15)) | G54: =IF(ISBLANK(G15), " ",IF(ISTEXT(G15),0,G15)) | H54: =IF(ISBLANK(H15), " ",IF(ISTEXT(H15),0,H15)) | I54: =IF(ISBLANK(I15), " ",IF(ISTEXT(I15),0,I15)) | J54: =IF(ISBLANK(J15), " ",IF(ISTEXT(J15),0,J15)) | K54: =IF(ISBLANK(K15), " ",IF(ISTEXT(K15),0,K15)) | L54: =IF(ISBLANK(L15), " ",IF(ISTEXT(L15),0,L15)) | ... S54: =IF(ISBLANK(S15), " ",IF(ISTEXT(S15),0,S15))
E55: =IF(ISBLANK(E16), " ",IF(ISTEXT(E16),0,E16)) | F55: =IF(ISBLANK(F16), " ",IF(ISTEXT(F16),0,F16)) | G55: =IF(ISBLANK(G16), " ",IF(ISTEXT(G16),0,G16)) | H55: =IF(ISBLANK(H16), " ",IF(ISTEXT(H16),0,H16)) | I55: =IF(ISBLANK(I16), " ",IF(ISTEXT(I16),0,I16)) | J55: =IF(ISBLANK(J16), " ",IF(ISTEXT(J16),0,J16)) | K55: =IF(ISBLANK(K16), " ",IF(ISTEXT(K16),0,K16)) | L55: =IF(ISBLANK(L16), " ",IF(ISTEXT(L16),0,L16)) | ... S55: =IF(ISBLANK(S16), " ",IF(ISTEXT(S16),0,S16))
E56: =IF(ISBLANK(E17), " ",IF(ISTEXT(E17),0,E17)) | F56: =IF(ISBLANK(F17), " ",IF(ISTEXT(F17),0,F17)) | G56: =IF(ISBLANK(G17), " ",IF(ISTEXT(G17),0,G17)) | H56: =IF(ISBLANK(H17), " ",IF(ISTEXT(H17),0,H17)) | I56: =IF(ISBLANK(I17), " ",IF(ISTEXT(I17),0,I17)) | J56: =IF(ISBLANK(J17), " ",IF(ISTEXT(J17),0,J17)) | K56: =IF(ISBLANK(K17), " ",IF(ISTEXT(K17),0,K17)) | L56: =IF(ISBLANK(L17), " ",IF(ISTEXT(L17),0,L17)) | ... S56: =IF(ISBLANK(S17), " ",IF(ISTEXT(S17),0,S17))
E57: =IF(ISBLANK(E18), " ",IF(ISTEXT(E18),0,E18)) | F57: =IF(ISBLANK(F18), " ",IF(ISTEXT(F18),0,F18)) | G57: =IF(ISBLANK(G18), " ",IF(ISTEXT(G18),0,G18)) | H57: =IF(ISBLANK(H18), " ",IF(ISTEXT(H18),0,H18)) | I57: =IF(ISBLANK(I18), " ",IF(ISTEXT(I18),0,I18)) | J57: =IF(ISBLANK(J18), " ",IF(ISTEXT(J18),0,J18)) | K57: =IF(ISBLANK(K18), " ",IF(ISTEXT(K18),0,K18)) | L57: =IF(ISBLANK(L18), " ",IF(ISTEXT(L18),0,L18)) | ... S57: =IF(ISBLANK(S18), " ",IF(ISTEXT(S18),0,S18))
... E75: =IF(ISBLANK(E36), " ",IF(ISTEXT(E36),0,E36)) | F75: =IF(ISBLANK(F36), " ",IF(ISTEXT(F36),0,F36)) | G75: =IF(ISBLANK(G36), " ",IF(ISTEXT(G36),0,G36)) | H75: =IF(ISBLANK(H36), " ",IF(ISTEXT(H36),0,H36)) | I75: =IF(ISBLANK(I36), " ",IF(ISTEXT(I36),0,I36)) | J75: =IF(ISBLANK(J36), " ",IF(ISTEXT(J36),0,J36)) | K75: =IF(ISBLANK(K36), " ",IF(ISTEXT(K36),0,K36)) | L75: =IF(ISBLANK(L36), " ",IF(ISTEXT(L36),0,L36)) | ... S75: =IF(ISBLANK(S36), " ",IF(ISTEXT(S36),0,S36))
C76: Geomean | E76: =IF(ISBLANK(E6)," ",IF(ISTEXT(E6),1,E6)) | F76: =IF(ISBLANK(F6)," ",IF(ISTEXT(F6),1,F6)) | G76: =IF(ISBLANK(G6)," ",IF(ISTEXT(G6),1,G6)) | H76: =IF(ISBLANK(H6)," ",IF(ISTEXT(H6),1,H6)) | I76: =IF(ISBLANK(I6)," ",IF(ISTEXT(I6),1,I6)) | J76: =IF(ISBLANK(J6)," ",IF(ISTEXT(J6),1,J6)) | K76: =IF(ISBLANK(K6)," ",IF(ISTEXT(K6),1,K6)) | L76: =IF(ISBLANK(L6)," ",IF(ISTEXT(L6),1,L6)) | ... S76: =IF(ISBLANK(S6)," ",IF(ISTEXT(S6),1,S6))
...

Sheet Certification Page
A1: Sampling Person(s) | K1: Certified Laboratories
A2: Name: | K2: Name:
A3: Name: | K3: Name:
A4: Does all monitoring data and sampling frequencies meet the requirements in Attachment A of your permit?
A5: If the facility is non-compliant, please explain in the space below the reason(s) the facility was not in compliance. Provide in your explanation the date(s) of the non-compliance and describe the corrective action(s) taken. Attach additional sheets if necessary.
A8: Operator in Responsible Charge (ORC) Certification | K8: Permittee Certification
A9: ORC: | K9: Permittee:
A10: Certification No.: | K10: Signing Official:
A11: Grade: | E11: Phone Number: | K11: Signing Official's Title:
A12: Has the ORC changed since the previous NDMR? | K12: Phone Number: | P12: Permit Expiration:
A15: Signature | I15: Date | K15: Signature | R15: Date
A16: By this signature, I certify that this report is accurrate and complete to the best of my knowledge. | K16: I certify, under penalty of law, that this document and all attachments were prepared under my direction or supervision in accordance with a system designed to assure that all qualified personnel properly gathered and evaluated the information submitted. Based on my inquiry of the person or persons who manage the system, or those persons directly responsible for gathering the information, the information submitted is, to the best of my knowledge and belief, true, accurate, and complete. I am aware that there are significant penalties for submitting false information, including the possibility of fines and imprisonment for knowing violations.
A18: Mail Original and Two Copies to:
A19: Division of Water Resources
A20: Information Processing Unit
A21: 1617 Mail Service Center
A22: Raleigh, North Carolina 27699-1617

Sheet PCS Parameter Codes
B1: User Friendly Name | C1: Official Parameter Name | D1: DWQ Accepted Units
A2: 00010 | B2: Temperature | C2: Temperature, Water Deg. Centigrade | D2: ºC
A3: 00076 | B3: Turbidity | C3: Turbidity, HCH Turbidimeter | D3: NTU
A4: 00092 | B4: Flow - Maximum | C4: Flow, Maximum Flow Range | D4: GPD
A5: 00094 | B5: Conductivity | C5: Conductivity | D5: µΩ
A6: 00125 | B6: Dichlorobenzene | C6: Dichlorobenzene (Isomers) M/P In Water ug/l | D6: µg/L
A7: 00300 | B7: Dissolved Oxygen | C7: DO, Oxygen, Dissolved | D7: mg/L
A8: 00310 | B8: BOD5 | C8: BOD, 5-Day (20 Deg. C) | D8: mg/L
A9: 00340 | B9: COD | C9: COD, Oxygen Demand, Chem. (High Level) | D9: mg/L
A10: 00400 | B10: pH | C10: pH | D10: su
A11: 00480 | B11: Salinity | C11: Salinity | D11: mg/L
A12: 00515 | B12: Total Filterable Residue | C12: Residue, Tot Fltrble (dried at 105C) | D12: mg/L
A13: 00530 | B13: Total Suspended Solids | C13: Solids, Total Suspended | D13: mg/L
... A48: 31504 | B48: Total Coliform | C48: Coliform, Total MF, Immed,LES Endo Agar | D48: #/100 mL
A49: 31505 | B49: Total Coliform | C49: Coliform, Tot, MPN, Completed, (100 mL) | D49: MPN/100 mL
A50: 31613 | B50: Fecal Coliform | C50: Coliform, Fecal MF, M-FC Agar,44.5C,24hr | D50: #/100 mL
A51: 31616 | B51: Fecal Coliform | C51: Coliform, Fecal MF, M-FC Broth,44.5C | D51: #/100 mL
A52: 32106 | B52: Chloroform | C52: Chloroform | D52: mg/L
A53: 32730 | B53: Phenolics - Recoverable | C53: Phenolics, Total Recoverable | D53: mg/L
A54: 32730 | B54: Phenols | D54: mg/L
A55: 34469 | B55: Pyrene | C55: Pyrene | D55: µg/L
A56: 34694 | B56: Phenol - Single | C56: Phenol, Single Compound | D56: mg/L
A57: 38260 | B57: Surfactants | C57: Surfactants (MBAS) | D57: mg/L
A58: 50050 | B58: Flow | C58: Flow, in conduit or thru treatment plant | D58: GPD
A59: 50060 | B59: Total Residual Chlorine | C59: Chlorine, Total Residual | D59: mg/L
A60: 70295 | B60: Total Dissolved Solids | C60: Solids, Total Dissolved | D60: mg/L
A61: 70300 | B61: Total Dissolved Solids | C61: Solids, Total Dissolved- 180 Deg.C | D61: mg/L
A62: 70318 | B62: % Solids | C62: Solids, Total, Percent | D62: %
A63: 71880 | B63: Formaldehyde | C63: Formaldehyde | D63: mg/L
A64: 71900 | B64: Mercury | C64: Mercury, Total (as Hg) | D64: mg/L
A65: 78732 | B65: Volatile Compounds | C65: Volatile Compounds, (GC/MS) | D65: Yes/No
A66: 80082 | B66: Carbonaceous BOD | C66: BOD, Carbonaceous 05 Day, 20C | D66: mg/L
A67: 81639 | B67: Total Kjeldahl Nitrogen | C67: Nitrogen Kjeldalh, Total (TKN) | D67: lbs/ac
A68: 81688 | B68: Ethylene Glycol | C68: Ethylene glycol | D68: µg/L
A69: 82385 | B69: Nitrogen Oxides | C69: Nitrogen Oxides (as N) | D69: mg/L
A70: 82546 | B70: Water Level | C70: Water level, distance from measuring point | D70: ft
A71: CO310 | B71: BOD5 - Conc. | C71: BOD, 5-Day (20 Deg. C) - Concentration | D71: mg/L
A72: CO530 | B72: TSS - Conc. | C72: Solids, Total Suspended - Concentration | D72: mg/L
A73: CO600 | B73: Total Nitrogen - Conc. | C73: Nitrogen, Total (as N) - Concentration | D73: mg/L
A74: CO610 | B74: Ammonia - Conc. | C74: Nitrogen, Ammonia Total (as N) - Concentration | D74: mg/L
...

Sheet Dropdown Menu
A2: January | B2: Alamance | C2: 2011 | D2: 001 | E2: Calculated | F2: Estimate
A3: February | B3: Alexander | C3: =1+C2 -> 2012 | D3: 002 | E3: Composite | F3: Recorder
A4: March | B4: Alleghany | C4: =1+C3 -> 2013 | D4: 003 | E4: Grab
A5: April | B5: Anson | C5: =1+C4 -> 2014 | D5: 004 | E5: Recorder
A6: May | B6: Ashe | C6: =1+C5 -> 2015 | D6: 005
A7: June | B7: Avery | C7: =1+C6 -> 2016 | D7: 006
A8: July | B8: Beaufort | C8: =1+C7 -> 2017 | D8: 007
A9: August | B9: Bertie | C9: =1+C8 -> 2018 | D9: 008
A10: September | B10: Bladen | C10: =1+C9 -> 2019 | D10: 009
A11: October | B11: Brunswick | C11: =1+C10 -> 2020 | D11: 010
A12: November | B12: Buncombe | C12: =1+C11 -> 2021 | D12: 011
A13: December | B13: Burke | C13: =1+C12 -> 2022 | D13: 012
B14: Cabarrus | C14: =1+C13 -> 2023 | D14: 013
B15: Caldwell | C15: =1+C14 -> 2024 | D15: 014
B16: Camden | C16: =1+C15 -> 2025 | D16: 015
B17: Carteret | C17: =1+C16 -> 2026
B18: Caswell | C18: =1+C17 -> 2027
B19: Catawba | C19: =1+C18 -> 2028
B20: Chatham | C20: =1+C19 -> 2029
B21: Cherokee | C21: =1+C20 -> 2030
B22: Chowan
B23: Clay
B24: Cleveland
B25: Columbus
B26: Craven
B27: Cumberland
B28: Currituck
B29: Dare
B30: Davidson
B31: Davie
B32: Duplin
B33: Durham
... B101: Yancey
